[2023-11-23T05:24:35.067+0000] {taskinstance.py:1125} INFO - Dependencies all met for dep_context=non-requeueable deps ti=<TaskInstance: dag_sf_crimes.load_url manual__2023-11-23T05:24:27.688891+00:00 [queued]>
[2023-11-23T05:24:35.166+0000] {taskinstance.py:1125} INFO - Dependencies all met for dep_context=requeueable deps ti=<TaskInstance: dag_sf_crimes.load_url manual__2023-11-23T05:24:27.688891+00:00 [queued]>
[2023-11-23T05:24:35.168+0000] {taskinstance.py:1331} INFO - Starting attempt 1 of 2
[2023-11-23T05:24:36.071+0000] {taskinstance.py:1350} INFO - Executing <Task(PythonOperator): load_url> on 2023-11-23 05:24:27.688891+00:00
[2023-11-23T05:24:36.100+0000] {standard_task_runner.py:57} INFO - Started process 357905 to run task
[2023-11-23T05:24:36.153+0000] {standard_task_runner.py:84} INFO - Running: ['airflow', 'tasks', 'run', 'dag_sf_crimes', 'load_url', 'manual__2023-11-23T05:24:27.688891+00:00', '--job-id', '22', '--raw', '--subdir', 'DAGS_FOLDER/dag_sf_crimes_raw.py', '--cfg-path', '/tmp/tmpevfbokzq']
[2023-11-23T05:24:36.186+0000] {standard_task_runner.py:85} INFO - Job 22: Subtask load_url
[2023-11-23T05:24:36.648+0000] {task_command.py:410} INFO - Running <TaskInstance: dag_sf_crimes.load_url manual__2023-11-23T05:24:27.688891+00:00 [running]> on host jarvis
[2023-11-23T05:24:37.780+0000] {taskinstance.py:1568} INFO - Exporting env vars: AIRFLOW_CTX_DAG_OWNER='airflow' AIRFLOW_CTX_DAG_ID='dag_sf_crimes' AIRFLOW_CTX_TASK_ID='load_url' AIRFLOW_CTX_EXECUTION_DATE='2023-11-23T05:24:27.688891+00:00' AIRFLOW_CTX_TRY_NUMBER='1' AIRFLOW_CTX_DAG_RUN_ID='manual__2023-11-23T05:24:27.688891+00:00'
[2023-11-23T05:24:37.783+0000] {taskinstance.py:1847} ERROR - Task failed with exception
Traceback (most recent call last):
  File "/usr/local/lib/python3.10/dist-packages/airflow/operators/python.py", line 181, in execute
    return_value = self.execute_callable()
  File "/usr/local/lib/python3.10/dist-packages/airflow/operators/python.py", line 198, in execute_callable
    return self.python_callable(*self.op_args, **self.op_kwargs)
  File "/home/mani-dev/airflow/dags/utils/load_url.py", line 4, in load_url
    response = requests.get(url)
  File "/usr/local/lib/python3.10/dist-packages/requests/api.py", line 73, in get
    return request("get", url, params=params, **kwargs)
  File "/usr/local/lib/python3.10/dist-packages/requests/api.py", line 59, in request
    return session.request(method=method, url=url, **kwargs)
  File "/usr/local/lib/python3.10/dist-packages/requests/sessions.py", line 573, in request
    prep = self.prepare_request(req)
  File "/usr/local/lib/python3.10/dist-packages/requests/sessions.py", line 484, in prepare_request
    p.prepare(
  File "/usr/local/lib/python3.10/dist-packages/requests/models.py", line 368, in prepare
    self.prepare_url(url, params)
  File "/usr/local/lib/python3.10/dist-packages/requests/models.py", line 439, in prepare_url
    raise MissingSchema(
requests.exceptions.MissingSchema: Invalid URL 'www.google.com': No scheme supplied. Perhaps you meant https://www.google.com?
[2023-11-23T05:24:37.836+0000] {taskinstance.py:1368} INFO - Marking task as UP_FOR_RETRY. dag_id=dag_sf_crimes, task_id=load_url, execution_date=20231123T052427, start_date=20231123T052435, end_date=20231123T052437
[2023-11-23T05:24:38.303+0000] {standard_task_runner.py:104} ERROR - Failed to execute job 22 for task load_url (Invalid URL 'www.google.com': No scheme supplied. Perhaps you meant https://www.google.com?; 357905)
[2023-11-23T05:24:38.396+0000] {local_task_job_runner.py:232} INFO - Task exited with return code 1
[2023-11-23T05:24:39.168+0000] {taskinstance.py:2674} INFO - 0 downstream tasks scheduled from follow-on schedule check
