[2023-11-23T17:58:03.721+0000] {taskinstance.py:1125} INFO - Dependencies all met for dep_context=non-requeueable deps ti=<TaskInstance: dag_SFCrimes_data_bqload.load_to_bq_task manual__2023-11-23T17:58:01.711169+00:00 [queued]>
[2023-11-23T17:58:03.750+0000] {taskinstance.py:1125} INFO - Dependencies all met for dep_context=requeueable deps ti=<TaskInstance: dag_SFCrimes_data_bqload.load_to_bq_task manual__2023-11-23T17:58:01.711169+00:00 [queued]>
[2023-11-23T17:58:03.751+0000] {taskinstance.py:1331} INFO - Starting attempt 1 of 2
[2023-11-23T17:58:03.820+0000] {taskinstance.py:1350} INFO - Executing <Task(PythonOperator): load_to_bq_task> on 2023-11-23 17:58:01.711169+00:00
[2023-11-23T17:58:03.829+0000] {standard_task_runner.py:57} INFO - Started process 454492 to run task
[2023-11-23T17:58:03.834+0000] {standard_task_runner.py:84} INFO - Running: ['airflow', 'tasks', 'run', 'dag_SFCrimes_data_bqload', 'load_to_bq_task', 'manual__2023-11-23T17:58:01.711169+00:00', '--job-id', '653', '--raw', '--subdir', 'DAGS_FOLDER/curated/dag_sf_crimes_bqload.py', '--cfg-path', '/tmp/tmpzpvlrhkp']
[2023-11-23T17:58:03.838+0000] {standard_task_runner.py:85} INFO - Job 653: Subtask load_to_bq_task
[2023-11-23T17:58:03.991+0000] {task_command.py:410} INFO - Running <TaskInstance: dag_SFCrimes_data_bqload.load_to_bq_task manual__2023-11-23T17:58:01.711169+00:00 [running]> on host jarvis
[2023-11-23T17:58:04.506+0000] {taskinstance.py:1568} INFO - Exporting env vars: AIRFLOW_CTX_DAG_OWNER='airflow' AIRFLOW_CTX_DAG_ID='dag_SFCrimes_data_bqload' AIRFLOW_CTX_TASK_ID='load_to_bq_task' AIRFLOW_CTX_EXECUTION_DATE='2023-11-23T17:58:01.711169+00:00' AIRFLOW_CTX_TRY_NUMBER='1' AIRFLOW_CTX_DAG_RUN_ID='manual__2023-11-23T17:58:01.711169+00:00'
[2023-11-23T18:00:21.481+0000] {taskinstance.py:1847} ERROR - Task failed with exception
Traceback (most recent call last):
  File "/usr/local/lib/python3.10/dist-packages/urllib3/connectionpool.py", line 703, in urlopen
    httplib_response = self._make_request(
  File "/usr/local/lib/python3.10/dist-packages/urllib3/connectionpool.py", line 449, in _make_request
    six.raise_from(e, None)
  File "<string>", line 3, in raise_from
  File "/usr/local/lib/python3.10/dist-packages/urllib3/connectionpool.py", line 444, in _make_request
    httplib_response = conn.getresponse()
  File "/usr/lib/python3.10/http/client.py", line 1375, in getresponse
    response.begin()
  File "/usr/lib/python3.10/http/client.py", line 318, in begin
    version, status, reason = self._read_status()
  File "/usr/lib/python3.10/http/client.py", line 287, in _read_status
    raise RemoteDisconnected("Remote end closed connection without"
http.client.RemoteDisconnected: Remote end closed connection without response

During handling of the above exception, another exception occurred:

Traceback (most recent call last):
  File "/usr/local/lib/python3.10/dist-packages/requests/adapters.py", line 487, in send
    resp = conn.urlopen(
  File "/usr/local/lib/python3.10/dist-packages/urllib3/connectionpool.py", line 787, in urlopen
    retries = retries.increment(
  File "/usr/local/lib/python3.10/dist-packages/urllib3/util/retry.py", line 550, in increment
    raise six.reraise(type(error), error, _stacktrace)
  File "/usr/local/lib/python3.10/dist-packages/urllib3/packages/six.py", line 769, in reraise
    raise value.with_traceback(tb)
  File "/usr/local/lib/python3.10/dist-packages/urllib3/connectionpool.py", line 703, in urlopen
    httplib_response = self._make_request(
  File "/usr/local/lib/python3.10/dist-packages/urllib3/connectionpool.py", line 449, in _make_request
    six.raise_from(e, None)
  File "<string>", line 3, in raise_from
  File "/usr/local/lib/python3.10/dist-packages/urllib3/connectionpool.py", line 444, in _make_request
    httplib_response = conn.getresponse()
  File "/usr/lib/python3.10/http/client.py", line 1375, in getresponse
    response.begin()
  File "/usr/lib/python3.10/http/client.py", line 318, in begin
    version, status, reason = self._read_status()
  File "/usr/lib/python3.10/http/client.py", line 287, in _read_status
    raise RemoteDisconnected("Remote end closed connection without"
urllib3.exceptions.ProtocolError: ('Connection aborted.', RemoteDisconnected('Remote end closed connection without response'))

During handling of the above exception, another exception occurred:

Traceback (most recent call last):
  File "/usr/local/lib/python3.10/dist-packages/airflow/operators/python.py", line 181, in execute
    return_value = self.execute_callable()
  File "/usr/local/lib/python3.10/dist-packages/airflow/operators/python.py", line 198, in execute_callable
    return self.python_callable(*self.op_args, **self.op_kwargs)
  File "/home/mani-dev/airflow/dags/curated/dag_sf_crimes_bqload.py", line 37, in load_bq_raw
    job.result()
  File "/home/mani-dev/.local/lib/python3.10/site-packages/google/cloud/bigquery/job/base.py", line 922, in result
    return super(_AsyncJob, self).result(timeout=timeout, **kwargs)
  File "/home/mani-dev/.local/lib/python3.10/site-packages/google/api_core/future/polling.py", line 256, in result
    self._blocking_poll(timeout=timeout, retry=retry, polling=polling)
  File "/home/mani-dev/.local/lib/python3.10/site-packages/google/api_core/future/polling.py", line 137, in _blocking_poll
    polling(self._done_or_raise)(retry=retry)
  File "/home/mani-dev/.local/lib/python3.10/site-packages/google/api_core/retry.py", line 372, in retry_wrapped_func
    return retry_target(
  File "/home/mani-dev/.local/lib/python3.10/site-packages/google/api_core/retry.py", line 207, in retry_target
    result = target()
  File "/home/mani-dev/.local/lib/python3.10/site-packages/google/api_core/future/polling.py", line 119, in _done_or_raise
    if not self.done(retry=retry):
  File "/home/mani-dev/.local/lib/python3.10/site-packages/google/cloud/bigquery/job/base.py", line 889, in done
    self.reload(retry=retry, timeout=timeout)
  File "/home/mani-dev/.local/lib/python3.10/site-packages/google/cloud/bigquery/job/base.py", line 781, in reload
    api_response = client._call_api(
  File "/home/mani-dev/.local/lib/python3.10/site-packages/google/cloud/bigquery/client.py", line 808, in _call_api
    return call()
  File "/home/mani-dev/.local/lib/python3.10/site-packages/google/cloud/_http/__init__.py", line 482, in api_request
    response = self._make_request(
  File "/home/mani-dev/.local/lib/python3.10/site-packages/google/cloud/_http/__init__.py", line 341, in _make_request
    return self._do_request(
  File "/home/mani-dev/.local/lib/python3.10/site-packages/google/cloud/_http/__init__.py", line 379, in _do_request
    return self.http.request(
  File "/home/mani-dev/.local/lib/python3.10/site-packages/google/auth/transport/requests.py", line 542, in request
    response = super(AuthorizedSession, self).request(
  File "/usr/local/lib/python3.10/dist-packages/requests/sessions.py", line 587, in request
    resp = self.send(prep, **send_kwargs)
  File "/usr/local/lib/python3.10/dist-packages/requests/sessions.py", line 701, in send
    r = adapter.send(request, **kwargs)
  File "/usr/local/lib/python3.10/dist-packages/requests/adapters.py", line 502, in send
    raise ConnectionError(err, request=request)
requests.exceptions.ConnectionError: ('Connection aborted.', RemoteDisconnected('Remote end closed connection without response'))
[2023-11-23T18:00:21.587+0000] {taskinstance.py:1368} INFO - Marking task as UP_FOR_RETRY. dag_id=dag_SFCrimes_data_bqload, task_id=load_to_bq_task, execution_date=20231123T175801, start_date=20231123T175803, end_date=20231123T180021
[2023-11-23T18:00:21.673+0000] {standard_task_runner.py:104} ERROR - Failed to execute job 653 for task load_to_bq_task (('Connection aborted.', RemoteDisconnected('Remote end closed connection without response')); 454492)
[2023-11-23T18:00:21.736+0000] {local_task_job_runner.py:232} INFO - Task exited with return code 1
[2023-11-23T18:00:21.854+0000] {taskinstance.py:2674} INFO - 0 downstream tasks scheduled from follow-on schedule check
