[2023-11-23T06:53:17.172+0000] {taskinstance.py:1125} INFO - Dependencies all met for dep_context=non-requeueable deps ti=<TaskInstance: dag_SFCrimes_data_bqload.load_to_bq_task scheduled__2023-11-22T17:00:00+00:00 [queued]>
[2023-11-23T06:53:17.203+0000] {taskinstance.py:1125} INFO - Dependencies all met for dep_context=requeueable deps ti=<TaskInstance: dag_SFCrimes_data_bqload.load_to_bq_task scheduled__2023-11-22T17:00:00+00:00 [queued]>
[2023-11-23T06:53:17.204+0000] {taskinstance.py:1331} INFO - Starting attempt 2 of 2
[2023-11-23T06:53:17.279+0000] {taskinstance.py:1350} INFO - Executing <Task(PythonOperator): load_to_bq_task> on 2023-11-22 17:00:00+00:00
[2023-11-23T06:53:17.288+0000] {standard_task_runner.py:57} INFO - Started process 392660 to run task
[2023-11-23T06:53:17.294+0000] {standard_task_runner.py:84} INFO - Running: ['airflow', 'tasks', 'run', 'dag_SFCrimes_data_bqload', 'load_to_bq_task', 'scheduled__2023-11-22T17:00:00+00:00', '--job-id', '640', '--raw', '--subdir', 'DAGS_FOLDER/curated/dag_sf_crimes_bqload.py', '--cfg-path', '/tmp/tmpbnv6dimr']
[2023-11-23T06:53:17.299+0000] {standard_task_runner.py:85} INFO - Job 640: Subtask load_to_bq_task
[2023-11-23T06:53:17.484+0000] {task_command.py:410} INFO - Running <TaskInstance: dag_SFCrimes_data_bqload.load_to_bq_task scheduled__2023-11-22T17:00:00+00:00 [running]> on host jarvis
[2023-11-23T06:53:17.968+0000] {taskinstance.py:1568} INFO - Exporting env vars: AIRFLOW_CTX_DAG_OWNER='airflow' AIRFLOW_CTX_DAG_ID='dag_SFCrimes_data_bqload' AIRFLOW_CTX_TASK_ID='load_to_bq_task' AIRFLOW_CTX_EXECUTION_DATE='2023-11-22T17:00:00+00:00' AIRFLOW_CTX_TRY_NUMBER='2' AIRFLOW_CTX_DAG_RUN_ID='scheduled__2023-11-22T17:00:00+00:00'
[2023-11-23T06:53:20.204+0000] {taskinstance.py:1847} ERROR - Task failed with exception
Traceback (most recent call last):
  File "/home/mani-dev/.local/lib/python3.10/site-packages/google/cloud/bigquery/client.py", line 2477, in load_table_from_file
    response = self._do_resumable_upload(
  File "/home/mani-dev/.local/lib/python3.10/site-packages/google/cloud/bigquery/client.py", line 2879, in _do_resumable_upload
    upload, transport = self._initiate_resumable_upload(
  File "/home/mani-dev/.local/lib/python3.10/site-packages/google/cloud/bigquery/client.py", line 2952, in _initiate_resumable_upload
    upload.initiate(
  File "/home/mani-dev/.local/lib/python3.10/site-packages/google/resumable_media/requests/upload.py", line 420, in initiate
    return _request_helpers.wait_and_retry(
  File "/home/mani-dev/.local/lib/python3.10/site-packages/google/resumable_media/requests/_request_helpers.py", line 155, in wait_and_retry
    response = func()
  File "/home/mani-dev/.local/lib/python3.10/site-packages/google/resumable_media/requests/upload.py", line 416, in retriable_request
    self._process_initiate_response(result)
  File "/home/mani-dev/.local/lib/python3.10/site-packages/google/resumable_media/_upload.py", line 518, in _process_initiate_response
    _helpers.require_status_code(
  File "/home/mani-dev/.local/lib/python3.10/site-packages/google/resumable_media/_helpers.py", line 108, in require_status_code
    raise common.InvalidResponse(
google.resumable_media.common.InvalidResponse: ('Request failed with status code', 403, 'Expected one of', <HTTPStatus.OK: 200>, <HTTPStatus.CREATED: 201>)

During handling of the above exception, another exception occurred:

Traceback (most recent call last):
  File "/usr/local/lib/python3.10/dist-packages/airflow/operators/python.py", line 181, in execute
    return_value = self.execute_callable()
  File "/usr/local/lib/python3.10/dist-packages/airflow/operators/python.py", line 198, in execute_callable
    return self.python_callable(*self.op_args, **self.op_kwargs)
  File "/home/mani-dev/airflow/dags/curated/dag_sf_crimes_bqload.py", line 34, in load_bq_raw
    job = client.load_table_from_file(source_file, table_ref, job_config=job_config)
  File "/home/mani-dev/.local/lib/python3.10/site-packages/google/cloud/bigquery/client.py", line 2485, in load_table_from_file
    raise exceptions.from_http_response(exc.response)
google.api_core.exceptions.Forbidden: 403 POST https://bigquery.googleapis.com/upload/bigquery/v2/projects/hakoona-matata-298704/jobs?uploadType=resumable: Access Denied: Project hakoona-matata-298704: User does not have bigquery.jobs.create permission in project hakoona-matata-298704.
[2023-11-23T06:53:20.238+0000] {taskinstance.py:1368} INFO - Marking task as FAILED. dag_id=dag_SFCrimes_data_bqload, task_id=load_to_bq_task, execution_date=20231122T170000, start_date=20231123T065317, end_date=20231123T065320
[2023-11-23T06:53:20.312+0000] {standard_task_runner.py:104} ERROR - Failed to execute job 640 for task load_to_bq_task (403 POST https://bigquery.googleapis.com/upload/bigquery/v2/projects/hakoona-matata-298704/jobs?uploadType=resumable: Access Denied: Project hakoona-matata-298704: User does not have bigquery.jobs.create permission in project hakoona-matata-298704.; 392660)
[2023-11-23T06:53:20.367+0000] {local_task_job_runner.py:232} INFO - Task exited with return code 1
[2023-11-23T06:53:20.441+0000] {taskinstance.py:2674} INFO - 0 downstream tasks scheduled from follow-on schedule check
[2023-11-23T19:35:13.945+0000] {taskinstance.py:1125} INFO - Dependencies all met for dep_context=non-requeueable deps ti=<TaskInstance: dag_SFCrimes_data_bqload.load_to_bq_task scheduled__2023-11-22T17:00:00+00:00 [queued]>
[2023-11-23T19:35:13.978+0000] {taskinstance.py:1125} INFO - Dependencies all met for dep_context=requeueable deps ti=<TaskInstance: dag_SFCrimes_data_bqload.load_to_bq_task scheduled__2023-11-22T17:00:00+00:00 [queued]>
[2023-11-23T19:35:13.979+0000] {taskinstance.py:1331} INFO - Starting attempt 2 of 2
[2023-11-23T19:35:14.016+0000] {taskinstance.py:1350} INFO - Executing <Task(PythonOperator): load_to_bq_task> on 2023-11-22 17:00:00+00:00
[2023-11-23T19:35:14.026+0000] {standard_task_runner.py:57} INFO - Started process 466437 to run task
[2023-11-23T19:35:14.033+0000] {standard_task_runner.py:84} INFO - Running: ['airflow', 'tasks', 'run', 'dag_SFCrimes_data_bqload', 'load_to_bq_task', 'scheduled__2023-11-22T17:00:00+00:00', '--job-id', '682', '--raw', '--subdir', 'DAGS_FOLDER/curated/dag_sf_crimes_bqload.py', '--cfg-path', '/tmp/tmpsk0b59zj']
[2023-11-23T19:35:14.037+0000] {standard_task_runner.py:85} INFO - Job 682: Subtask load_to_bq_task
[2023-11-23T19:35:14.218+0000] {task_command.py:410} INFO - Running <TaskInstance: dag_SFCrimes_data_bqload.load_to_bq_task scheduled__2023-11-22T17:00:00+00:00 [running]> on host jarvis
[2023-11-23T19:35:14.539+0000] {taskinstance.py:1568} INFO - Exporting env vars: AIRFLOW_CTX_DAG_OWNER='airflow' AIRFLOW_CTX_DAG_ID='dag_SFCrimes_data_bqload' AIRFLOW_CTX_TASK_ID='load_to_bq_task' AIRFLOW_CTX_EXECUTION_DATE='2023-11-22T17:00:00+00:00' AIRFLOW_CTX_TRY_NUMBER='2' AIRFLOW_CTX_DAG_RUN_ID='scheduled__2023-11-22T17:00:00+00:00'
[2023-11-23T19:35:16.271+0000] {taskinstance.py:1847} ERROR - Task failed with exception
Traceback (most recent call last):
  File "/usr/local/lib/python3.10/dist-packages/airflow/operators/python.py", line 181, in execute
    return_value = self.execute_callable()
  File "/usr/local/lib/python3.10/dist-packages/airflow/operators/python.py", line 198, in execute_callable
    return self.python_callable(*self.op_args, **self.op_kwargs)
  File "/home/mani-dev/airflow/dags/curated/dag_sf_crimes_bqload.py", line 32, in load_bq_raw
    with open(source_file, "rb") as source_file:
FileNotFoundError: [Errno 2] No such file or directory: '/mnt/ssd/external/projects/sf_crimes/SFcrimes_2023112319.csv'
[2023-11-23T19:35:16.304+0000] {taskinstance.py:1368} INFO - Marking task as FAILED. dag_id=dag_SFCrimes_data_bqload, task_id=load_to_bq_task, execution_date=20231122T170000, start_date=20231123T193513, end_date=20231123T193516
[2023-11-23T19:35:16.378+0000] {standard_task_runner.py:104} ERROR - Failed to execute job 682 for task load_to_bq_task ([Errno 2] No such file or directory: '/mnt/ssd/external/projects/sf_crimes/SFcrimes_2023112319.csv'; 466437)
[2023-11-23T19:35:16.440+0000] {local_task_job_runner.py:232} INFO - Task exited with return code 1
[2023-11-23T19:35:16.498+0000] {taskinstance.py:2674} INFO - 0 downstream tasks scheduled from follow-on schedule check
