[2023-11-23T06:46:12.078+0000] {taskinstance.py:1125} INFO - Dependencies all met for dep_context=non-requeueable deps ti=<TaskInstance: dag_SFCrimes_data_bqload.load_to_bq_task scheduled__2023-11-22T05:00:00+00:00 [queued]>
[2023-11-23T06:46:12.107+0000] {taskinstance.py:1125} INFO - Dependencies all met for dep_context=requeueable deps ti=<TaskInstance: dag_SFCrimes_data_bqload.load_to_bq_task scheduled__2023-11-22T05:00:00+00:00 [queued]>
[2023-11-23T06:46:12.108+0000] {taskinstance.py:1331} INFO - Starting attempt 1 of 2
[2023-11-23T06:46:12.150+0000] {taskinstance.py:1350} INFO - Executing <Task(PythonOperator): load_to_bq_task> on 2023-11-22 05:00:00+00:00
[2023-11-23T06:46:12.159+0000] {standard_task_runner.py:57} INFO - Started process 391675 to run task
[2023-11-23T06:46:12.165+0000] {standard_task_runner.py:84} INFO - Running: ['airflow', 'tasks', 'run', 'dag_SFCrimes_data_bqload', 'load_to_bq_task', 'scheduled__2023-11-22T05:00:00+00:00', '--job-id', '637', '--raw', '--subdir', 'DAGS_FOLDER/curated/dag_sf_crimes_bqload.py', '--cfg-path', '/tmp/tmpm4bmdsbv']
[2023-11-23T06:46:12.170+0000] {standard_task_runner.py:85} INFO - Job 637: Subtask load_to_bq_task
[2023-11-23T06:46:12.330+0000] {task_command.py:410} INFO - Running <TaskInstance: dag_SFCrimes_data_bqload.load_to_bq_task scheduled__2023-11-22T05:00:00+00:00 [running]> on host jarvis
[2023-11-23T06:46:12.856+0000] {taskinstance.py:1568} INFO - Exporting env vars: AIRFLOW_CTX_DAG_OWNER='airflow' AIRFLOW_CTX_DAG_ID='dag_SFCrimes_data_bqload' AIRFLOW_CTX_TASK_ID='load_to_bq_task' AIRFLOW_CTX_EXECUTION_DATE='2023-11-22T05:00:00+00:00' AIRFLOW_CTX_TRY_NUMBER='1' AIRFLOW_CTX_DAG_RUN_ID='scheduled__2023-11-22T05:00:00+00:00'
[2023-11-23T06:46:15.602+0000] {taskinstance.py:1847} ERROR - Task failed with exception
Traceback (most recent call last):
  File "/home/mani-dev/.local/lib/python3.10/site-packages/google/cloud/bigquery/client.py", line 2477, in load_table_from_file
    response = self._do_resumable_upload(
  File "/home/mani-dev/.local/lib/python3.10/site-packages/google/cloud/bigquery/client.py", line 2879, in _do_resumable_upload
    upload, transport = self._initiate_resumable_upload(
  File "/home/mani-dev/.local/lib/python3.10/site-packages/google/cloud/bigquery/client.py", line 2952, in _initiate_resumable_upload
    upload.initiate(
  File "/home/mani-dev/.local/lib/python3.10/site-packages/google/resumable_media/requests/upload.py", line 420, in initiate
    return _request_helpers.wait_and_retry(
  File "/home/mani-dev/.local/lib/python3.10/site-packages/google/resumable_media/requests/_request_helpers.py", line 155, in wait_and_retry
    response = func()
  File "/home/mani-dev/.local/lib/python3.10/site-packages/google/resumable_media/requests/upload.py", line 416, in retriable_request
    self._process_initiate_response(result)
  File "/home/mani-dev/.local/lib/python3.10/site-packages/google/resumable_media/_upload.py", line 518, in _process_initiate_response
    _helpers.require_status_code(
  File "/home/mani-dev/.local/lib/python3.10/site-packages/google/resumable_media/_helpers.py", line 108, in require_status_code
    raise common.InvalidResponse(
google.resumable_media.common.InvalidResponse: ('Request failed with status code', 403, 'Expected one of', <HTTPStatus.OK: 200>, <HTTPStatus.CREATED: 201>)

During handling of the above exception, another exception occurred:

Traceback (most recent call last):
  File "/usr/local/lib/python3.10/dist-packages/airflow/operators/python.py", line 181, in execute
    return_value = self.execute_callable()
  File "/usr/local/lib/python3.10/dist-packages/airflow/operators/python.py", line 198, in execute_callable
    return self.python_callable(*self.op_args, **self.op_kwargs)
  File "/home/mani-dev/airflow/dags/curated/dag_sf_crimes_bqload.py", line 34, in load_bq_raw
    job = client.load_table_from_file(source_file, table_ref, job_config=job_config)
  File "/home/mani-dev/.local/lib/python3.10/site-packages/google/cloud/bigquery/client.py", line 2485, in load_table_from_file
    raise exceptions.from_http_response(exc.response)
google.api_core.exceptions.Forbidden: 403 POST https://bigquery.googleapis.com/upload/bigquery/v2/projects/hakoona-matata-298704/jobs?uploadType=resumable: Access Denied: Project hakoona-matata-298704: User does not have bigquery.jobs.create permission in project hakoona-matata-298704.
[2023-11-23T06:46:15.642+0000] {taskinstance.py:1368} INFO - Marking task as UP_FOR_RETRY. dag_id=dag_SFCrimes_data_bqload, task_id=load_to_bq_task, execution_date=20231122T050000, start_date=20231123T064612, end_date=20231123T064615
[2023-11-23T06:46:15.725+0000] {standard_task_runner.py:104} ERROR - Failed to execute job 637 for task load_to_bq_task (403 POST https://bigquery.googleapis.com/upload/bigquery/v2/projects/hakoona-matata-298704/jobs?uploadType=resumable: Access Denied: Project hakoona-matata-298704: User does not have bigquery.jobs.create permission in project hakoona-matata-298704.; 391675)
[2023-11-23T06:46:15.772+0000] {local_task_job_runner.py:232} INFO - Task exited with return code 1
[2023-11-23T06:46:15.857+0000] {taskinstance.py:2674} INFO - 0 downstream tasks scheduled from follow-on schedule check
[2023-11-23T19:30:09.807+0000] {taskinstance.py:1125} INFO - Dependencies all met for dep_context=non-requeueable deps ti=<TaskInstance: dag_SFCrimes_data_bqload.load_to_bq_task scheduled__2023-11-22T05:00:00+00:00 [queued]>
[2023-11-23T19:30:09.843+0000] {taskinstance.py:1125} INFO - Dependencies all met for dep_context=requeueable deps ti=<TaskInstance: dag_SFCrimes_data_bqload.load_to_bq_task scheduled__2023-11-22T05:00:00+00:00 [queued]>
[2023-11-23T19:30:09.844+0000] {taskinstance.py:1331} INFO - Starting attempt 1 of 2
[2023-11-23T19:30:09.927+0000] {taskinstance.py:1350} INFO - Executing <Task(PythonOperator): load_to_bq_task> on 2023-11-22 05:00:00+00:00
[2023-11-23T19:30:09.940+0000] {standard_task_runner.py:57} INFO - Started process 465874 to run task
[2023-11-23T19:30:09.950+0000] {standard_task_runner.py:84} INFO - Running: ['airflow', 'tasks', 'run', 'dag_SFCrimes_data_bqload', 'load_to_bq_task', 'scheduled__2023-11-22T05:00:00+00:00', '--job-id', '678', '--raw', '--subdir', 'DAGS_FOLDER/curated/dag_sf_crimes_bqload.py', '--cfg-path', '/tmp/tmpeni_6bxn']
[2023-11-23T19:30:09.962+0000] {standard_task_runner.py:85} INFO - Job 678: Subtask load_to_bq_task
[2023-11-23T19:30:10.150+0000] {task_command.py:410} INFO - Running <TaskInstance: dag_SFCrimes_data_bqload.load_to_bq_task scheduled__2023-11-22T05:00:00+00:00 [running]> on host jarvis
[2023-11-23T19:30:10.689+0000] {taskinstance.py:1568} INFO - Exporting env vars: AIRFLOW_CTX_DAG_OWNER='airflow' AIRFLOW_CTX_DAG_ID='dag_SFCrimes_data_bqload' AIRFLOW_CTX_TASK_ID='load_to_bq_task' AIRFLOW_CTX_EXECUTION_DATE='2023-11-22T05:00:00+00:00' AIRFLOW_CTX_TRY_NUMBER='1' AIRFLOW_CTX_DAG_RUN_ID='scheduled__2023-11-22T05:00:00+00:00'
[2023-11-23T19:30:12.592+0000] {taskinstance.py:1847} ERROR - Task failed with exception
Traceback (most recent call last):
  File "/usr/local/lib/python3.10/dist-packages/airflow/operators/python.py", line 181, in execute
    return_value = self.execute_callable()
  File "/usr/local/lib/python3.10/dist-packages/airflow/operators/python.py", line 198, in execute_callable
    return self.python_callable(*self.op_args, **self.op_kwargs)
  File "/home/mani-dev/airflow/dags/curated/dag_sf_crimes_bqload.py", line 32, in load_bq_raw
    with open(source_file, "rb") as source_file:
FileNotFoundError: [Errno 2] No such file or directory: '/mnt/ssd/external/projects/sf_crimes/SFcrimes_2023112319.csv'
[2023-11-23T19:30:12.626+0000] {taskinstance.py:1368} INFO - Marking task as UP_FOR_RETRY. dag_id=dag_SFCrimes_data_bqload, task_id=load_to_bq_task, execution_date=20231122T050000, start_date=20231123T193009, end_date=20231123T193012
[2023-11-23T19:30:12.707+0000] {standard_task_runner.py:104} ERROR - Failed to execute job 678 for task load_to_bq_task ([Errno 2] No such file or directory: '/mnt/ssd/external/projects/sf_crimes/SFcrimes_2023112319.csv'; 465874)
[2023-11-23T19:30:12.758+0000] {local_task_job_runner.py:232} INFO - Task exited with return code 1
[2023-11-23T19:30:12.816+0000] {taskinstance.py:2674} INFO - 0 downstream tasks scheduled from follow-on schedule check
