[2023-12-03T08:29:15.262+0000] {taskinstance.py:1125} INFO - Dependencies all met for dep_context=non-requeueable deps ti=<TaskInstance: dag_SFCrimes_data_bqload.load_to_bq_task manual__2023-12-03T08:29:13.603873+00:00 [queued]>
[2023-12-03T08:29:15.297+0000] {taskinstance.py:1125} INFO - Dependencies all met for dep_context=requeueable deps ti=<TaskInstance: dag_SFCrimes_data_bqload.load_to_bq_task manual__2023-12-03T08:29:13.603873+00:00 [queued]>
[2023-12-03T08:29:15.297+0000] {taskinstance.py:1331} INFO - Starting attempt 1 of 2
[2023-12-03T08:29:15.341+0000] {taskinstance.py:1350} INFO - Executing <Task(PythonOperator): load_to_bq_task> on 2023-12-03 08:29:13.603873+00:00
[2023-12-03T08:29:15.351+0000] {standard_task_runner.py:57} INFO - Started process 579544 to run task
[2023-12-03T08:29:15.360+0000] {standard_task_runner.py:84} INFO - Running: ['airflow', 'tasks', 'run', 'dag_SFCrimes_data_bqload', 'load_to_bq_task', 'manual__2023-12-03T08:29:13.603873+00:00', '--job-id', '79', '--raw', '--subdir', 'DAGS_FOLDER/dag_sf_crimes_bqload.py', '--cfg-path', '/tmp/tmpkh905866']
[2023-12-03T08:29:15.368+0000] {standard_task_runner.py:85} INFO - Job 79: Subtask load_to_bq_task
[2023-12-03T08:29:15.543+0000] {task_command.py:410} INFO - Running <TaskInstance: dag_SFCrimes_data_bqload.load_to_bq_task manual__2023-12-03T08:29:13.603873+00:00 [running]> on host jarvis
[2023-12-03T08:29:16.095+0000] {taskinstance.py:1568} INFO - Exporting env vars: AIRFLOW_CTX_DAG_OWNER='airflow' AIRFLOW_CTX_DAG_ID='dag_SFCrimes_data_bqload' AIRFLOW_CTX_TASK_ID='load_to_bq_task' AIRFLOW_CTX_EXECUTION_DATE='2023-12-03T08:29:13.603873+00:00' AIRFLOW_CTX_TRY_NUMBER='1' AIRFLOW_CTX_DAG_RUN_ID='manual__2023-12-03T08:29:13.603873+00:00'
[2023-12-03T08:29:23.828+0000] {taskinstance.py:1847} ERROR - Task failed with exception
Traceback (most recent call last):
  File "/usr/local/lib/python3.10/dist-packages/airflow/operators/python.py", line 181, in execute
    return_value = self.execute_callable()
  File "/usr/local/lib/python3.10/dist-packages/airflow/operators/python.py", line 198, in execute_callable
    return self.python_callable(*self.op_args, **self.op_kwargs)
  File "/home/mani-dev/airflow/dags/dag_sf_crimes_bqload.py", line 36, in load_bq_raw
    job.result()
  File "/home/mani-dev/.local/lib/python3.10/site-packages/google/cloud/bigquery/job/base.py", line 922, in result
    return super(_AsyncJob, self).result(timeout=timeout, **kwargs)
  File "/home/mani-dev/.local/lib/python3.10/site-packages/google/api_core/future/polling.py", line 261, in result
    raise self._exception
google.api_core.exceptions.BadRequest: 400 Error while reading data, error message: CSV processing encountered too many errors, giving up. Rows: 2001; errors: 1; max bad: 0; error percent: 0
[2023-12-03T08:29:23.869+0000] {taskinstance.py:1368} INFO - Marking task as UP_FOR_RETRY. dag_id=dag_SFCrimes_data_bqload, task_id=load_to_bq_task, execution_date=20231203T082913, start_date=20231203T082915, end_date=20231203T082923
[2023-12-03T08:29:23.951+0000] {standard_task_runner.py:104} ERROR - Failed to execute job 79 for task load_to_bq_task (400 Error while reading data, error message: CSV processing encountered too many errors, giving up. Rows: 2001; errors: 1; max bad: 0; error percent: 0; 579544)
[2023-12-03T08:29:24.012+0000] {local_task_job_runner.py:232} INFO - Task exited with return code 1
[2023-12-03T08:29:24.064+0000] {taskinstance.py:2674} INFO - 0 downstream tasks scheduled from follow-on schedule check
