[2023-11-23T17:55:35.708+0000] {taskinstance.py:1125} INFO - Dependencies all met for dep_context=non-requeueable deps ti=<TaskInstance: dag_SFCrimes_data_bqload.load_to_bq_task scheduled__2023-11-23T05:00:00+00:00 [queued]>
[2023-11-23T17:55:35.738+0000] {taskinstance.py:1125} INFO - Dependencies all met for dep_context=requeueable deps ti=<TaskInstance: dag_SFCrimes_data_bqload.load_to_bq_task scheduled__2023-11-23T05:00:00+00:00 [queued]>
[2023-11-23T17:55:35.739+0000] {taskinstance.py:1331} INFO - Starting attempt 2 of 2
[2023-11-23T17:55:35.812+0000] {taskinstance.py:1350} INFO - Executing <Task(PythonOperator): load_to_bq_task> on 2023-11-23 05:00:00+00:00
[2023-11-23T17:55:35.820+0000] {standard_task_runner.py:57} INFO - Started process 454157 to run task
[2023-11-23T17:55:35.825+0000] {standard_task_runner.py:84} INFO - Running: ['airflow', 'tasks', 'run', 'dag_SFCrimes_data_bqload', 'load_to_bq_task', 'scheduled__2023-11-23T05:00:00+00:00', '--job-id', '650', '--raw', '--subdir', 'DAGS_FOLDER/curated/dag_sf_crimes_bqload.py', '--cfg-path', '/tmp/tmp2hf41gt6']
[2023-11-23T17:55:35.829+0000] {standard_task_runner.py:85} INFO - Job 650: Subtask load_to_bq_task
[2023-11-23T17:55:35.988+0000] {task_command.py:410} INFO - Running <TaskInstance: dag_SFCrimes_data_bqload.load_to_bq_task scheduled__2023-11-23T05:00:00+00:00 [running]> on host jarvis
[2023-11-23T17:55:36.566+0000] {taskinstance.py:1568} INFO - Exporting env vars: AIRFLOW_CTX_DAG_OWNER='airflow' AIRFLOW_CTX_DAG_ID='dag_SFCrimes_data_bqload' AIRFLOW_CTX_TASK_ID='load_to_bq_task' AIRFLOW_CTX_EXECUTION_DATE='2023-11-23T05:00:00+00:00' AIRFLOW_CTX_TRY_NUMBER='2' AIRFLOW_CTX_DAG_RUN_ID='scheduled__2023-11-23T05:00:00+00:00'
[2023-11-23T17:55:38.258+0000] {taskinstance.py:1847} ERROR - Task failed with exception
Traceback (most recent call last):
  File "/usr/local/lib/python3.10/dist-packages/airflow/operators/python.py", line 181, in execute
    return_value = self.execute_callable()
  File "/usr/local/lib/python3.10/dist-packages/airflow/operators/python.py", line 198, in execute_callable
    return self.python_callable(*self.op_args, **self.op_kwargs)
  File "/home/mani-dev/airflow/dags/curated/dag_sf_crimes_bqload.py", line 34, in load_bq_raw
    job = client.load_table_from_file(source_file, table_ref, job_config=job_config)
  File "/home/mani-dev/.local/lib/python3.10/site-packages/google/cloud/bigquery/client.py", line 2477, in load_table_from_file
    response = self._do_resumable_upload(
  File "/home/mani-dev/.local/lib/python3.10/site-packages/google/cloud/bigquery/client.py", line 2879, in _do_resumable_upload
    upload, transport = self._initiate_resumable_upload(
  File "/home/mani-dev/.local/lib/python3.10/site-packages/google/cloud/bigquery/client.py", line 2952, in _initiate_resumable_upload
    upload.initiate(
  File "/home/mani-dev/.local/lib/python3.10/site-packages/google/resumable_media/requests/upload.py", line 420, in initiate
    return _request_helpers.wait_and_retry(
  File "/home/mani-dev/.local/lib/python3.10/site-packages/google/resumable_media/requests/_request_helpers.py", line 155, in wait_and_retry
    response = func()
  File "/home/mani-dev/.local/lib/python3.10/site-packages/google/resumable_media/requests/upload.py", line 412, in retriable_request
    result = transport.request(
  File "/home/mani-dev/.local/lib/python3.10/site-packages/google/auth/transport/requests.py", line 538, in request
    self.credentials.before_request(auth_request, method, url, request_headers)
  File "/home/mani-dev/.local/lib/python3.10/site-packages/google/auth/credentials.py", line 175, in before_request
    self.refresh(request)
  File "/home/mani-dev/.local/lib/python3.10/site-packages/google/oauth2/service_account.py", line 438, in refresh
    access_token, expiry, _ = _client.jwt_grant(
  File "/home/mani-dev/.local/lib/python3.10/site-packages/google/oauth2/_client.py", line 308, in jwt_grant
    response_data = _token_endpoint_request(
  File "/home/mani-dev/.local/lib/python3.10/site-packages/google/oauth2/_client.py", line 279, in _token_endpoint_request
    _handle_error_response(response_data, retryable_error)
  File "/home/mani-dev/.local/lib/python3.10/site-packages/google/oauth2/_client.py", line 72, in _handle_error_response
    raise exceptions.RefreshError(
google.auth.exceptions.RefreshError: ('invalid_grant: Invalid grant: account not found', {'error': 'invalid_grant', 'error_description': 'Invalid grant: account not found'})
[2023-11-23T17:55:38.294+0000] {taskinstance.py:1368} INFO - Marking task as FAILED. dag_id=dag_SFCrimes_data_bqload, task_id=load_to_bq_task, execution_date=20231123T050000, start_date=20231123T175535, end_date=20231123T175538
[2023-11-23T17:55:38.369+0000] {standard_task_runner.py:104} ERROR - Failed to execute job 650 for task load_to_bq_task (('invalid_grant: Invalid grant: account not found', {'error': 'invalid_grant', 'error_description': 'Invalid grant: account not found'}); 454157)
[2023-11-23T17:55:38.414+0000] {local_task_job_runner.py:232} INFO - Task exited with return code 1
[2023-11-23T17:55:38.484+0000] {taskinstance.py:2674} INFO - 0 downstream tasks scheduled from follow-on schedule check
[2023-11-23T19:35:13.964+0000] {taskinstance.py:1125} INFO - Dependencies all met for dep_context=non-requeueable deps ti=<TaskInstance: dag_SFCrimes_data_bqload.load_to_bq_task scheduled__2023-11-23T05:00:00+00:00 [queued]>
[2023-11-23T19:35:13.997+0000] {taskinstance.py:1125} INFO - Dependencies all met for dep_context=requeueable deps ti=<TaskInstance: dag_SFCrimes_data_bqload.load_to_bq_task scheduled__2023-11-23T05:00:00+00:00 [queued]>
[2023-11-23T19:35:13.998+0000] {taskinstance.py:1331} INFO - Starting attempt 2 of 2
[2023-11-23T19:35:14.046+0000] {taskinstance.py:1350} INFO - Executing <Task(PythonOperator): load_to_bq_task> on 2023-11-23 05:00:00+00:00
[2023-11-23T19:35:14.062+0000] {standard_task_runner.py:57} INFO - Started process 466440 to run task
[2023-11-23T19:35:14.072+0000] {standard_task_runner.py:84} INFO - Running: ['airflow', 'tasks', 'run', 'dag_SFCrimes_data_bqload', 'load_to_bq_task', 'scheduled__2023-11-23T05:00:00+00:00', '--job-id', '683', '--raw', '--subdir', 'DAGS_FOLDER/curated/dag_sf_crimes_bqload.py', '--cfg-path', '/tmp/tmpq0rbrmcs']
[2023-11-23T19:35:14.076+0000] {standard_task_runner.py:85} INFO - Job 683: Subtask load_to_bq_task
[2023-11-23T19:35:14.260+0000] {task_command.py:410} INFO - Running <TaskInstance: dag_SFCrimes_data_bqload.load_to_bq_task scheduled__2023-11-23T05:00:00+00:00 [running]> on host jarvis
[2023-11-23T19:35:14.591+0000] {taskinstance.py:1568} INFO - Exporting env vars: AIRFLOW_CTX_DAG_OWNER='airflow' AIRFLOW_CTX_DAG_ID='dag_SFCrimes_data_bqload' AIRFLOW_CTX_TASK_ID='load_to_bq_task' AIRFLOW_CTX_EXECUTION_DATE='2023-11-23T05:00:00+00:00' AIRFLOW_CTX_TRY_NUMBER='2' AIRFLOW_CTX_DAG_RUN_ID='scheduled__2023-11-23T05:00:00+00:00'
[2023-11-23T19:35:16.594+0000] {taskinstance.py:1847} ERROR - Task failed with exception
Traceback (most recent call last):
  File "/usr/local/lib/python3.10/dist-packages/airflow/operators/python.py", line 181, in execute
    return_value = self.execute_callable()
  File "/usr/local/lib/python3.10/dist-packages/airflow/operators/python.py", line 198, in execute_callable
    return self.python_callable(*self.op_args, **self.op_kwargs)
  File "/home/mani-dev/airflow/dags/curated/dag_sf_crimes_bqload.py", line 32, in load_bq_raw
    with open(source_file, "rb") as source_file:
FileNotFoundError: [Errno 2] No such file or directory: '/mnt/ssd/external/projects/sf_crimes/SFcrimes_2023112319.csv'
[2023-11-23T19:35:16.631+0000] {taskinstance.py:1368} INFO - Marking task as FAILED. dag_id=dag_SFCrimes_data_bqload, task_id=load_to_bq_task, execution_date=20231123T050000, start_date=20231123T193513, end_date=20231123T193516
[2023-11-23T19:35:16.699+0000] {standard_task_runner.py:104} ERROR - Failed to execute job 683 for task load_to_bq_task ([Errno 2] No such file or directory: '/mnt/ssd/external/projects/sf_crimes/SFcrimes_2023112319.csv'; 466440)
[2023-11-23T19:35:16.742+0000] {local_task_job_runner.py:232} INFO - Task exited with return code 1
[2023-11-23T19:35:16.799+0000] {taskinstance.py:2674} INFO - 0 downstream tasks scheduled from follow-on schedule check
