[2023-12-04T20:51:24.849+0000] {taskinstance.py:1125} INFO - Dependencies all met for dep_context=non-requeueable deps ti=<TaskInstance: dag_SFCrimes_data_bqload.load_to_bq_task manual__2023-12-04T20:32:03.211935+00:00 [queued]>
[2023-12-04T20:51:24.879+0000] {taskinstance.py:1125} INFO - Dependencies all met for dep_context=requeueable deps ti=<TaskInstance: dag_SFCrimes_data_bqload.load_to_bq_task manual__2023-12-04T20:32:03.211935+00:00 [queued]>
[2023-12-04T20:51:24.880+0000] {taskinstance.py:1331} INFO - Starting attempt 5 of 5
[2023-12-04T20:51:24.953+0000] {taskinstance.py:1350} INFO - Executing <Task(PythonOperator): load_to_bq_task> on 2023-12-04 20:32:03.211935+00:00
[2023-12-04T20:51:24.963+0000] {standard_task_runner.py:57} INFO - Started process 965814 to run task
[2023-12-04T20:51:24.969+0000] {standard_task_runner.py:84} INFO - Running: ['airflow', 'tasks', 'run', 'dag_SFCrimes_data_bqload', 'load_to_bq_task', 'manual__2023-12-04T20:32:03.211935+00:00', '--job-id', '109', '--raw', '--subdir', 'DAGS_FOLDER/dag_sf_crimes_bqload.py', '--cfg-path', '/tmp/tmp2_h5er36']
[2023-12-04T20:51:24.972+0000] {standard_task_runner.py:85} INFO - Job 109: Subtask load_to_bq_task
[2023-12-04T20:51:25.129+0000] {task_command.py:410} INFO - Running <TaskInstance: dag_SFCrimes_data_bqload.load_to_bq_task manual__2023-12-04T20:32:03.211935+00:00 [running]> on host jarvis
[2023-12-04T20:51:25.651+0000] {taskinstance.py:1568} INFO - Exporting env vars: AIRFLOW_CTX_DAG_OWNER='airflow' AIRFLOW_CTX_DAG_ID='dag_SFCrimes_data_bqload' AIRFLOW_CTX_TASK_ID='load_to_bq_task' AIRFLOW_CTX_EXECUTION_DATE='2023-12-04T20:32:03.211935+00:00' AIRFLOW_CTX_TRY_NUMBER='5' AIRFLOW_CTX_DAG_RUN_ID='manual__2023-12-04T20:32:03.211935+00:00'
[2023-12-04T20:51:34.200+0000] {taskinstance.py:1847} ERROR - Task failed with exception
Traceback (most recent call last):
  File "/home/mani-dev/.local/lib/python3.10/site-packages/google/cloud/bigquery/client.py", line 2477, in load_table_from_file
    response = self._do_resumable_upload(
  File "/home/mani-dev/.local/lib/python3.10/site-packages/google/cloud/bigquery/client.py", line 2879, in _do_resumable_upload
    upload, transport = self._initiate_resumable_upload(
  File "/home/mani-dev/.local/lib/python3.10/site-packages/google/cloud/bigquery/client.py", line 2952, in _initiate_resumable_upload
    upload.initiate(
  File "/home/mani-dev/.local/lib/python3.10/site-packages/google/resumable_media/requests/upload.py", line 420, in initiate
    return _request_helpers.wait_and_retry(
  File "/home/mani-dev/.local/lib/python3.10/site-packages/google/resumable_media/requests/_request_helpers.py", line 155, in wait_and_retry
    response = func()
  File "/home/mani-dev/.local/lib/python3.10/site-packages/google/resumable_media/requests/upload.py", line 416, in retriable_request
    self._process_initiate_response(result)
  File "/home/mani-dev/.local/lib/python3.10/site-packages/google/resumable_media/_upload.py", line 518, in _process_initiate_response
    _helpers.require_status_code(
  File "/home/mani-dev/.local/lib/python3.10/site-packages/google/resumable_media/_helpers.py", line 108, in require_status_code
    raise common.InvalidResponse(
google.resumable_media.common.InvalidResponse: ('Request failed with status code', 400, 'Expected one of', <HTTPStatus.OK: 200>, <HTTPStatus.CREATED: 201>)

During handling of the above exception, another exception occurred:

Traceback (most recent call last):
  File "/usr/local/lib/python3.10/dist-packages/airflow/operators/python.py", line 181, in execute
    return_value = self.execute_callable()
  File "/usr/local/lib/python3.10/dist-packages/airflow/operators/python.py", line 198, in execute_callable
    return self.python_callable(*self.op_args, **self.op_kwargs)
  File "/home/mani-dev/airflow/dags/dag_sf_crimes_bqload.py", line 38, in load_bq_raw
    job = client.load_table_from_file(source_file, table_ref, job_config=job_config)
  File "/home/mani-dev/.local/lib/python3.10/site-packages/google/cloud/bigquery/client.py", line 2485, in load_table_from_file
    raise exceptions.from_http_response(exc.response)
google.api_core.exceptions.BadRequest: 400 POST https://bigquery.googleapis.com/upload/bigquery/v2/projects/hakoona-matata-298704/jobs?uploadType=resumable: No schema specified on job or table.
[2023-12-04T20:51:34.237+0000] {taskinstance.py:1368} INFO - Marking task as FAILED. dag_id=dag_SFCrimes_data_bqload, task_id=load_to_bq_task, execution_date=20231204T203203, start_date=20231204T205124, end_date=20231204T205134
[2023-12-04T20:51:34.315+0000] {standard_task_runner.py:104} ERROR - Failed to execute job 109 for task load_to_bq_task (400 POST https://bigquery.googleapis.com/upload/bigquery/v2/projects/hakoona-matata-298704/jobs?uploadType=resumable: No schema specified on job or table.; 965814)
[2023-12-04T20:51:34.382+0000] {local_task_job_runner.py:232} INFO - Task exited with return code 1
[2023-12-04T20:51:34.439+0000] {taskinstance.py:2674} INFO - 0 downstream tasks scheduled from follow-on schedule check
